[2023-12-16T12:00:20.944+0000] {taskinstance.py:1159} INFO - Dependencies all met for dep_context=non-requeueable deps ti=<TaskInstance: data_ops.load manual__2023-12-16T11:57:21.843732+00:00 [queued]>
[2023-12-16T12:00:20.947+0000] {taskinstance.py:1159} INFO - Dependencies all met for dep_context=requeueable deps ti=<TaskInstance: data_ops.load manual__2023-12-16T11:57:21.843732+00:00 [queued]>
[2023-12-16T12:00:20.947+0000] {taskinstance.py:1361} INFO - Starting attempt 1 of 1
[2023-12-16T12:00:20.952+0000] {taskinstance.py:1382} INFO - Executing <Task(_PythonDecoratedOperator): load> on 2023-12-16 11:57:21.843732+00:00
[2023-12-16T12:00:20.967+0000] {standard_task_runner.py:57} INFO - Started process 184 to run task
[2023-12-16T12:00:20.971+0000] {standard_task_runner.py:84} INFO - Running: ['***', 'tasks', 'run', 'data_ops', 'load', 'manual__2023-12-16T11:57:21.843732+00:00', '--job-id', '28', '--raw', '--subdir', 'DAGS_FOLDER/workflows_2.py', '--cfg-path', '/tmp/tmpex20k3qp']
[2023-12-16T12:00:20.972+0000] {standard_task_runner.py:85} INFO - Job 28: Subtask load
[2023-12-16T12:00:21.022+0000] {task_command.py:416} INFO - Running <TaskInstance: data_ops.load manual__2023-12-16T11:57:21.843732+00:00 [running]> on host 80e3f3cdf7f6
[2023-12-16T12:00:21.331+0000] {taskinstance.py:1662} INFO - Exporting env vars: AIRFLOW_CTX_DAG_OWNER='***' AIRFLOW_CTX_DAG_ID='data_ops' AIRFLOW_CTX_TASK_ID='load' AIRFLOW_CTX_EXECUTION_DATE='2023-12-16T11:57:21.843732+00:00' AIRFLOW_CTX_TRY_NUMBER='1' AIRFLOW_CTX_DAG_RUN_ID='manual__2023-12-16T11:57:21.843732+00:00'
[2023-12-16T12:00:21.337+0000] {taskinstance.py:1937} ERROR - Task failed with exception
Traceback (most recent call last):
  File "/home/airflow/.local/lib/python3.8/site-packages/airflow/decorators/base.py", line 221, in execute
    return_value = super().execute(context)
  File "/home/airflow/.local/lib/python3.8/site-packages/airflow/operators/python.py", line 192, in execute
    return_value = self.execute_callable()
  File "/home/airflow/.local/lib/python3.8/site-packages/airflow/operators/python.py", line 209, in execute_callable
    return self.python_callable(*self.op_args, **self.op_kwargs)
  File "/opt/airflow/dags/workflows_2.py", line 108, in load
    client = bigquery.Client()
  File "/home/airflow/.local/lib/python3.8/site-packages/google/cloud/bigquery/client.py", line 235, in __init__
    super(Client, self).__init__(
  File "/home/airflow/.local/lib/python3.8/site-packages/google/cloud/client/__init__.py", line 320, in __init__
    _ClientProjectMixin.__init__(self, project=project, credentials=credentials)
  File "/home/airflow/.local/lib/python3.8/site-packages/google/cloud/client/__init__.py", line 268, in __init__
    project = self._determine_default(project)
  File "/home/airflow/.local/lib/python3.8/site-packages/google/cloud/client/__init__.py", line 287, in _determine_default
    return _determine_default_project(project)
  File "/home/airflow/.local/lib/python3.8/site-packages/google/cloud/_helpers/__init__.py", line 152, in _determine_default_project
    _, project = google.auth.default()
  File "/home/airflow/.local/lib/python3.8/site-packages/google/auth/_default.py", line 657, in default
    credentials, project_id = checker()
  File "/home/airflow/.local/lib/python3.8/site-packages/google/auth/_default.py", line 650, in <lambda>
    lambda: _get_explicit_environ_credentials(quota_project_id=quota_project_id),
  File "/home/airflow/.local/lib/python3.8/site-packages/google/auth/_default.py", line 270, in _get_explicit_environ_credentials
    credentials, project_id = load_credentials_from_file(
  File "/home/airflow/.local/lib/python3.8/site-packages/google/auth/_default.py", line 114, in load_credentials_from_file
    raise exceptions.DefaultCredentialsError(
google.auth.exceptions.DefaultCredentialsError: File bicing_Gcloud_service.json was not found.
[2023-12-16T12:00:21.348+0000] {taskinstance.py:1400} INFO - Marking task as FAILED. dag_id=data_ops, task_id=load, execution_date=20231216T115721, start_date=20231216T120020, end_date=20231216T120021
[2023-12-16T12:00:21.355+0000] {standard_task_runner.py:104} ERROR - Failed to execute job 28 for task load (File bicing_Gcloud_service.json was not found.; 184)
[2023-12-16T12:00:21.388+0000] {local_task_job_runner.py:228} INFO - Task exited with return code 1
[2023-12-16T12:00:21.399+0000] {taskinstance.py:2778} INFO - 0 downstream tasks scheduled from follow-on schedule check
